<mujoco model="ur5">
    <compiler angle="radian" meshdir="meshes" />

    <option gravity="0 0 0" cone="elliptic" timestep="0.02" />

    <size njmax="500" nconmax="100" />

    <visual>
        <map znear="0.001" />
    </visual>

    <default>
        <light castshadow="false" diffuse="1 1 1" />
        <joint frictionloss="1" damping="1" />
        <camera fovy="60" />
        <motor gear="0.8"/>
        <velocity kv="10"/>
        <position kp="5"/>
    </default>

    <asset>
        <material name="Light" specular="0" shininess="0.6" reflectance="0.9" rgba="1 1 1 1" emission="0.7" />
    </asset>

    <worldbody>
        <body pos="-0.16 0.90 0.02" euler="4.71238898 0 3.14159265">
            <body euler="0 -0.82 0">
                <camera name="workbench_camera" euler="0.25 0 0" fovy="43" />
            </body>
        </body>
        <body pos="-1 1.52 0.64" euler="4.71238898 0 3.14159265">
            <body euler="-0.23 0 0">
                <camera name="upper_camera" euler="0 0.09 0" fovy="41" />
            </body>
        </body>

        <light directional="true" pos="-0.5 0.5 3" dir="0 0 -1" />
        <light directional="false" pos="-0.5 0.5 1.5" dir="0 -1 0" />

        <body name="base_link" pos="-0.175 0.175 0" quat="0.3826834324 0 0 0.9238795325" >
            <inertial pos="0 0 0" quat="0.5 0.5 -0.5 0.5" mass="4" diaginertia="0.0072 0.00443333 0.00443333" />

            <body name="shoulder_link" pos="0 0 0.089159">
                <inertial pos="0 0 0" mass="3.7" diaginertia="0.0102675 0.0102675 0.00666" />
                <joint name="joint1" pos="0 0 0" axis="0 0 1" />

                <body name="upper_arm_link" pos="0 0.13585 0" quat="0.707107 0 0.707107 0">
                    <inertial pos="0 0 0.28" mass="8.393" diaginertia="0.226891 0.226891 0.0151074" />
                    <joint name="joint2" pos="0 0 0" axis="0 1 0" />

                    <body name="forearm_link" pos="0 -0.1197 0.425">
                        <inertial pos="0 0 0.25" mass="2.275" diaginertia="0.0494433 0.0494433 0.004095" />

                        <!--camera name="forearm_camera" pos="0 0.1 0.07" euler="3.14159265 0 1.570796" /-->

                        <joint name="joint3" pos="0 0 0" axis="0 1 0" />

                        <body name="wrist1_link" pos="0 0 0.39225" quat="0.707107 0 0.707107 0">
                            <inertial pos="0 0 0" quat="0.5 0.5 -0.5 0.5" mass="1.219" diaginertia="0.21942 0.111173 0.111173" />
                            <joint name="joint4" pos="0 0 0" axis="0 1 0" />

                            <body name="wrist2_link" pos="0 0.093 0">
                                <inertial pos="0 0 0" quat="0.5 0.5 -0.5 0.5" mass="1.219" diaginertia="0.21942 0.111173 0.111173" />
                                <joint name="joint5" pos="0 0 0" axis="0 0 1" />

                                <body name="wrist3_link" pos="0 0 0.09465" quat="0.707107 0 -0.707107 0" >
                                    <inertial pos="0 0 0" quat="0.5 0.5 -0.5 0.5" mass="0.1879" diaginertia="0.033822 0.0171365 0.0171365" />
                                    <joint name="joint6" pos="0 0 0" axis="0 1 0" />

                                    <body name="ee_link" pos="0 0.0823 0" quat="0.707107 -0.707107 0 0">
                                        <inertial pos="0 0.0823 0" quat="0.707107 -0.707107 0 0" mass="0" diaginertia="0 0 0" />
                                        <geom name="light_2" type="sphere" size="0.005" pos="-0.035 0 0.0166" material="Light" />
                                    </body>
                                </body>
                            </body>
                        </body>
                    </body>
                </body>
            </body>
        </body>
    </worldbody>
</mujoco>
